Workbook

Sheet Valuation
A1: Alphabet | valuation framework
A2: USD millions. Operating DCF versus adjusted market EV; aggregate equity bridge retained. No per-share inputs or outputs.
A3: Selected scenario | B3: =Assumptions!B3 -> Base
A4: Valuation date | B4: =Assumptions!B4 -> 46320
A6: Market inputs / enterprise bridge | B6: Input | C6: Basis
A7: Market capitalisation | B7: ='Discount rate'!B7 -> 3916000 | C7: Common equity market value at the agreed valuation date; source directly, without diluted-share multiplication.
A8: Unpaid legal settlement claim proxy | B8: ='Financial assets'!B37 -> 12156 | C8: June legal accrual less known July payment; provisional carrying-value proxy, separate from recurring FCFF.
A9: US Treasury risk-free rate | B9: ='Sources and basis'!B89 -> 0.05 | C9: 23 October 2026 US Treasury 10-year par yield; source in Sources and basis.
A10: Operating-business levered beta | B10: ='Discount rate'!B16 -> 1.0758505 | C10: Bottom-up / cash-adjusted beta research
A11: Implied equity risk premium | B11: ='Discount rate'!B9 -> 0.042 | C11: Latest monthly ERP available at 25 October: 1 October 2026.
A12: Pre-tax cost of debt | B12: ='Discount rate'!B30 -> 0.054 | C12: Valuation-date borrowing yield
A13: Debt market value, ex finance leases | B13: ='Discount rate'!B22 -> 101586 | C13: Current and long-term financing claims
A14: Preferred market claim | B14: ='Discount rate'!B36 -> 17804.325 | C14: Mandatory conversion terms; avoid adding shares and claim together
A15: Preferred required return | B15: ='Discount rate'!B37 -> 0.09518572 | C15: Dividend and conversion economics
A16: Finance lease claim proxy | B16: ='Sources and basis'!B55 -> 2590 | C16: Lease PP&E is included; book value used as the market-value proxy (disclosed approximation)
A17: Non-controlling interest value | B17: =IF(ISNUMBER('Discount rate'!B50),'Discount rate'!B50,"") -> 7100 | C17: Book value, deducted in full; Waymo share not disclosed (may overstate claims by up to 7,100)
A18: Credited excess cash | B18: =IF(ISNUMBER('Financial assets'!B33),'Financial assets'!B33,"") -> 26051.53 | C18: Required operating cash excluded
A19: Credited marketable investments | B19: =IF(COUNT('Financial assets'!H7:H10)=4,SUM('Financial assets'!H7:H10),"") -> 170751.74 | C19: Liquidity restrictions and valuation uncertainty assessed
A20: Credited non-marketable investments | B20: =IF(COUNT('Financial assets'!H11:H12)=2,SUM('Financial assets'!H11:H12),"") -> 110463.2 | C20: Valuation uncertainty and taxes assessed
A21: Terminal growth | B21: =Assumptions!B197 -> 0.03 | C21: ="Base 3.0% (Bear 2.0%, Bull 3.5%); below WACC and the "&TEXT('Discount rate'!B8,"0.00%")&" Treasury yield" -> Base 3.0% (Bear 2.0%, Bull 3.5%); below WACC and the 5.00% Treasury yield
A22: Terminal return on capital | B22: =Transition!B25 -> 0.12 | C22: Base ceiling 12%, Bull 16%, Bear current WACC; also capped at each scenario's starting return. Terminal reinvestment = growth / return.
A23: Baseline reviewed for valuation | B23: FALSE | C23: Group sign-off remains pending. Estimated June-to-October cash bridge, tax bases and book-value NCI are disclosed approximations.
A24: Mid-year discounting (1 = on, 0 = year-end) | B24: 1 | C24: Cash flows assumed mid-period; H2 2026 stub at its midpoint; terminal value shifted once through Transition!G19.
A26: Cost of equity | B26: =IF(COUNT(B9:B11)=3,B9+B10*B11,"") -> 0.09518572
A27: Market value of common equity | B27: =IF(ISNUMBER(B7),B7,"") -> 3916000
A28: Total financing value | B28: =IF(AND(ISNUMBER(B27),COUNT(B13:B14)=2,ISNUMBER(B16)),SUM(B27,B13:B14,B16),"") -> 4037980.3
A29: WACC | B29: =IF(AND(COUNT(B12:B16)=5,ISNUMBER(B26),ISNUMBER(B28),B28>0),B27/B28*B26+(B13+B16)/B28*B12*(1-Assumptions!B5)+B14/B28*B15,"") -> 0.093830607 | C29: Indicative estimate; see Discount rate for dated evidence and approximation choices.
A30: Valuation readiness | B30: =IF(COUNT(B7:B22)<16,"Market / bridge inputs pending",IF(NOT(B23),"Baseline review pending",IF(OR(B29<=B21,B22<=B21),"Review terminal assumptions","Ready"))) -> Baseline review pending
A33: Discounted cash flow | B33: H2 2026 | C33: 2027 | D33: 2028 | E33: 2029 | F33: 2030 | G33: 2031
A34: Cash-flow date | B34: =DATE(2026,12,31) -> 46387 | C34: =DATE(2027,12,31) -> 46752 | D34: =DATE(2028,12,31) -> 47118 | E34: =DATE(2029,12,31) -> 47483 | F34: =DATE(2030,12,31) -> 47848 | G34: =DATE(2031,12,31) -> 48213
A35: Years from valuation date | B35: =YEARFRAC($B$4,B34,3)*IF($B$24=1,0.5,1) -> 0.091780822 | C35: =YEARFRAC($B$4,C34,3)-IF($B$24=1,0.5,0) -> 0.68356164 | D35: =YEARFRAC($B$4,D34,3)-IF($B$24=1,0.5,0) -> 1.6863014 | E35: =YEARFRAC($B$4,E34,3)-IF($B$24=1,0.5,0) -> 2.6863014 | F35: =YEARFRAC($B$4,F34,3)-IF($B$24=1,0.5,0) -> 3.6863014 | G35: =YEARFRAC($B$4,G34,3)-IF($B$24=1,0.5,0) -> 4.6863014
A36: Remaining-period fraction | B36: =(B34-$B$4)/(B34-DATE(2026,6,30)) -> 0.36413043 | C36: =1 -> 1 | D36: =1 -> 1 | E36: =1 -> 1 | F36: =1 -> 1 | G36: =1 -> 1
A37: Model FCFF | B37: ='Capital and FCFF'!B38 -> -28017.165 | C37: ='Capital and FCFF'!C38 -> 713.39555 | D37: ='Capital and FCFF'!D38 -> 45919.555 | E37: ='Capital and FCFF'!E38 -> 72623.186 | F37: ='Capital and FCFF'!F38 -> 109739.81 | G37: ='Capital and FCFF'!G38 -> 145130.84
A38: Cash flow after valuation date | B38: =B37*B36 -> -10201.902 | C38: =C37*C36 -> 713.39555 | D38: =D37*D36 -> 45919.555 | E38: =E37*E36 -> 72623.186 | F38: =F37*F36 -> 109739.81 | G38: =G37*G36 -> 145130.84
A39: Present value | B39: =IF(AND(ISNUMBER($B$29),$B$29>0),B38/(1+$B$29)^B35,"") -> -10118.271 | C39: =IF(AND(ISNUMBER($B$29),$B$29>0),C38/(1+$B$29)^C35,"") -> 670.97389 | D39: =IF(AND(ISNUMBER($B$29),$B$29>0),D38/(1+$B$29)^D35,"") -> 39474.452 | E39: =IF(AND(ISNUMBER($B$29),$B$29>0),E38/(1+$B$29)^E35,"") -> 57074.704 | F39: =IF(AND(ISNUMBER($B$29),$B$29>0),F38/(1+$B$29)^F35,"") -> 78846.514 | G39: =IF(AND(ISNUMBER($B$29),$B$29>0),G38/(1+$B$29)^G35,"") -> 95329.638
A42: Terminal NOPAT | B42: =Transition!H13 -> 286781.19
A43: Terminal reinvestment rate | B43: =Transition!H14 -> 0.25
A44: Terminal FCFF | B44: =Transition!H16 -> 215085.89
A45: Terminal value | B45: =IF(AND(ISNUMBER(B29),B29>B21,B22>B21),B44/(B29-B21),"") -> 3369635.7
A46: Present value of terminal value | B46: =IF(ISNUMBER(B45),B45/(1+B29)^Transition!G19,"") -> 1412821.8
...

Sheet Assumptions
A1: Alphabet | model assumptions
A2: PROVISIONAL BASELINE — editable scenarios; not a completed valuation or investment recommendation.
A3: Selected scenario | B3: Base
A4: Valuation date | B4: =DATE(2026,10,25) -> 46320
A5: Historical NOPAT tax benchmark | B5: 0.21
A6: Driver / scenario | B6: H2 2026 | C6: 2027 | D6: 2028 | E6: 2029 | F6: 2030 | G6: 2031 | H6: Rationale / evidence
A7: Search growth — active | B7: =INDEX(B8:B10,MATCH($B$3,$A8:$A10,0)) -> 0.17902223 | C7: =INDEX(C8:C10,MATCH($B$3,$A8:$A10,0)) -> 0.15 | D7: =INDEX(D8:D10,MATCH($B$3,$A8:$A10,0)) -> 0.13 | E7: =INDEX(E8:E10,MATCH($B$3,$A8:$A10,0)) -> 0.11 | F7: =INDEX(F8:F10,MATCH($B$3,$A8:$A10,0)) -> 0.09 | G7: =INDEX(G8:G10,MATCH($B$3,$A8:$A10,0)) -> 0.08 | H7: H2 base holds H1 YoY growth; later fade is provisional.
A8: Base | B8: ='Historical base'!E8/'Historical base'!D8-1 -> 0.17902223 | C8: 0.15 | D8: 0.13 | E8: 0.11 | F8: 0.09 | G8: 0.08
A9: Bull | B9: 0.22 | C9: 0.2 | D9: 0.18 | E9: 0.16 | F9: 0.14 | G9: 0.12
A10: Bear | B10: 0.1 | C10: 0.1 | D10: 0.08 | E10: 0.06 | F10: 0.04 | G10: 0.03
A12: YouTube advertising growth — active | B12: =INDEX(B13:B15,MATCH($B$3,$A13:$A15,0)) -> 0.11830369 | C12: =INDEX(C13:C15,MATCH($B$3,$A13:$A15,0)) -> 0.12 | D12: =INDEX(D13:D15,MATCH($B$3,$A13:$A15,0)) -> 0.11 | E12: =INDEX(E13:E15,MATCH($B$3,$A13:$A15,0)) -> 0.1 | F12: =INDEX(F13:F15,MATCH($B$3,$A13:$A15,0)) -> 0.09 | G12: =INDEX(G13:G15,MATCH($B$3,$A13:$A15,0)) -> 0.08 | H12: Advertising only; subscriptions remain within Services other revenue.
A13: Base | B13: ='Historical base'!E9/'Historical base'!D9-1 -> 0.11830369 | C13: 0.12 | D13: 0.11 | E13: 0.1 | F13: 0.09 | G13: 0.08
A14: Bull | B14: 0.16 | C14: 0.16 | D14: 0.15 | E14: 0.14 | F14: 0.13 | G14: 0.12
A15: Bear | B15: 0.07 | C15: 0.07 | D15: 0.06 | E15: 0.05 | F15: 0.04 | G15: 0.03
A17: Network growth — active | B17: =INDEX(B18:B20,MATCH($B$3,$A18:$A20,0)) -> -0.022997947 | C17: =INDEX(C18:C20,MATCH($B$3,$A18:$A20,0)) -> -0.03 | D17: =INDEX(D18:D20,MATCH($B$3,$A18:$A20,0)) -> -0.03 | E17: =INDEX(E18:E20,MATCH($B$3,$A18:$A20,0)) -> -0.02 | F17: =INDEX(F18:F20,MATCH($B$3,$A18:$A20,0)) -> -0.02 | G17: =INDEX(G18:G20,MATCH($B$3,$A18:$A20,0)) -> -0.02 | H17: Reflects recent contraction; scenarios are analyst inputs.
A18: Base | B18: ='Historical base'!E10/'Historical base'!D10-1 -> -0.022997947 | C18: -0.03 | D18: -0.03 | E18: -0.02 | F18: -0.02 | G18: -0.02
A19: Bull | B19: 0 | C19: 0 | D19: 0.01 | E19: 0.02 | F19: 0.02 | G19: 0.02
A20: Bear | B20: -0.08 | C20: -0.08 | D20: -0.07 | E20: -0.06 | F20: -0.05 | G20: -0.05
A22: Subscriptions / devices growth — active | B22: =INDEX(B23:B25,MATCH($B$3,$A23:$A25,0)) -> 0.17204152 | C22: =INDEX(C23:C25,MATCH($B$3,$A23:$A25,0)) -> 0.15 | D22: =INDEX(D23:D25,MATCH($B$3,$A23:$A25,0)) -> 0.13 | E22: =INDEX(E23:E25,MATCH($B$3,$A23:$A25,0)) -> 0.12 | F22: =INDEX(F23:F25,MATCH($B$3,$A23:$A25,0)) -> 0.1 | G22: =INDEX(G23:G25,MATCH($B$3,$A23:$A25,0)) -> 0.09 | H22: Includes subscriptions, platforms and devices.
A23: Base | B23: ='Historical base'!E11/'Historical base'!D11-1 -> 0.17204152 | C23: 0.15 | D23: 0.13 | E23: 0.12 | F23: 0.1 | G23: 0.09
A24: Bull | B24: 0.2 | C24: 0.2 | D24: 0.18 | E24: 0.16 | F24: 0.14 | G24: 0.13
A25: Bear | B25: 0.08 | C25: 0.08 | D25: 0.07 | E25: 0.06 | F25: 0.05 | G25: 0.04
A27: Cloud demand growth before backlog / delivery | B27: =INDEX(B28:B30,MATCH($B$3,$A28:$A30,0)) -> 0.73064441 | C27: =INDEX(C28:C30,MATCH($B$3,$A28:$A30,0)) -> 0.35 | D27: =INDEX(D28:D30,MATCH($B$3,$A28:$A30,0)) -> 0.25 | E27: =INDEX(E28:E30,MATCH($B$3,$A28:$A30,0)) -> 0.2 | F27: =INDEX(F28:F30,MATCH($B$3,$A28:$A30,0)) -> 0.16 | G27: =INDEX(G28:G30,MATCH($B$3,$A28:$A30,0)) -> 0.12 | H27: Reference demand taper; Cloud demand reconciles opening backlog, new business and delivery. Actual revenue growth is an output.
A28: Base | B28: ='Historical base'!E13/'Historical base'!D13-1 -> 0.73064441 | C28: 0.35 | D28: 0.25 | E28: 0.2 | F28: 0.16 | G28: 0.12
A29: Bull | B29: 0.85 | C29: 0.45 | D29: 0.35 | E29: 0.28 | F29: 0.23 | G29: 0.18
A30: Bear | B30: 0.45 | C30: 0.2 | D30: 0.15 | E30: 0.1 | F30: 0.08 | G30: 0.06
A32: Other Bets revenue growth — active | B32: =INDEX(B33:B35,MATCH($B$3,$A33:$A35,0)) -> 0.1 | C32: =INDEX(C33:C35,MATCH($B$3,$A33:$A35,0)) -> 0.1 | D32: =INDEX(D33:D35,MATCH($B$3,$A33:$A35,0)) -> 0.1 | E32: =INDEX(E33:E35,MATCH($B$3,$A33:$A35,0)) -> 0.1 | F32: =INDEX(F33:F35,MATCH($B$3,$A33:$A35,0)) -> 0.1 | G32: =INDEX(G33:G35,MATCH($B$3,$A33:$A35,0)) -> 0.1 | H32: Consolidated Other Bets, not a standalone Waymo valuation.
A33: Base | B33: 0.1 | C33: 0.1 | D33: 0.1 | E33: 0.1 | F33: 0.1 | G33: 0.1
A34: Bull | B34: 0.25 | C34: 0.25 | D34: 0.25 | E34: 0.2 | F34: 0.2 | G34: 0.2
A35: Bear | B35: 0 | C35: 0 | D35: 0 | E35: 0 | F35: 0 | G35: 0
A37: Services reference EBIT margin — active | B37: =INDEX(B38:B40,MATCH($B$3,$A38:$A40,0)) -> 0.4350869 | C37: =INDEX(C38:C40,MATCH($B$3,$A38:$A40,0)) -> 0.43 | D37: =INDEX(D38:D40,MATCH($B$3,$A38:$A40,0)) -> 0.43 | E37: =INDEX(E38:E40,MATCH($B$3,$A38:$A40,0)) -> 0.425 | F37: =INDEX(F38:F40,MATCH($B$3,$A38:$A40,0)) -> 0.42 | G37: =INDEX(G38:G40,MATCH($B$3,$A38:$A40,0)) -> 0.42 | H37: Common reference margin across cases; explicit TAC and AI-cost changes drive case differences.
A38: Base | B38: ='Historical base'!E26 -> 0.4350869 | C38: 0.43 | D38: 0.43 | E38: 0.425 | F38: 0.42 | G38: 0.42
A39: Bull | B39: =B38 -> 0.4350869 | C39: =C38 -> 0.43 | D39: =D38 -> 0.43 | E39: =E38 -> 0.425 | F39: =F38 -> 0.42 | G39: =G38 -> 0.42
A40: Bear | B40: =B38 -> 0.4350869 | C40: =C38 -> 0.43 | D40: =D38 -> 0.43 | E40: =E38 -> 0.425 | F40: =F38 -> 0.42 | G40: =G38 -> 0.42
A42: Cloud reference EBIT margin — active | B42: =INDEX(B43:B45,MATCH($B$3,$A43:$A45,0)) -> 0.34404858 | C42: =INDEX(C43:C45,MATCH($B$3,$A43:$A45,0)) -> 0.35 | D42: =INDEX(D43:D45,MATCH($B$3,$A43:$A45,0)) -> 0.36 | E42: =INDEX(E43:E45,MATCH($B$3,$A43:$A45,0)) -> 0.37 | F42: =INDEX(F43:F45,MATCH($B$3,$A43:$A45,0)) -> 0.38 | G42: =INDEX(G43:G45,MATCH($B$3,$A43:$A45,0)) -> 0.38 | H42: Reference margin; explicit capital schedule determines consolidated D&A.
A43: Base | B43: ='Historical base'!E27 -> 0.34404858 | C43: 0.35 | D43: 0.36 | E43: 0.37 | F43: 0.38 | G43: 0.38
A44: Bull | B44: 0.36 | C44: 0.38 | D44: 0.4 | E44: 0.41 | F44: 0.42 | G44: 0.42
A45: Bear | B45: 0.3 | C45: 0.29 | D45: 0.28 | E45: 0.28 | F45: 0.28 | G45: 0.28
A47: Other Bets cost growth — active | B47: =INDEX(B48:B50,MATCH($B$3,$A48:$A50,0)) -> 0.15 | C47: =INDEX(C48:C50,MATCH($B$3,$A48:$A50,0)) -> 0.15 | D47: =INDEX(D48:D50,MATCH($B$3,$A48:$A50,0)) -> 0.12 | E47: =INDEX(E48:E50,MATCH($B$3,$A48:$A50,0)) -> 0.1 | F47: =INDEX(F48:F50,MATCH($B$3,$A48:$A50,0)) -> 0.08 | G47: =INDEX(G48:G50,MATCH($B$3,$A48:$A50,0)) -> 0.05 | H47: Costs are positive loss magnitude; no speculative loss addback.
A48: Base | B48: 0.15 | C48: 0.15 | D48: 0.12 | E48: 0.1 | F48: 0.08 | G48: 0.05
...

Sheet Discount rate
A1: Alphabet | discount rate and financing claims
A2: USD millions except prices, percentages and ratios. Valuation/information cutoff: 25 October 2026; market closes: 23 October. June balance-sheet proxies and subsequent-event estimates are identified.
A3: Selected case | B3: =Assumptions!B3 -> Base
A4: Valuation date | B4: =Assumptions!B4 -> 46320
A6: Market input | B6: Value | C6: Basis / source
A7: Common-equity market capitalisation | B7: 3916000 | C7: 23 October 2026 group market capitalisation, rounded USDm. https://ycharts.com/companies/GOOGL/market_cap
A8: US Treasury yield | B8: ='Sources and basis'!B89 -> 0.05 | C8: 23 October 2026 US Treasury 10-year par yield: 5.00%. Treasury-based ERP convention.
A9: Damodaran implied ERP | B9: 0.042 | C9: 1 October 2026 implied ERP, trailing-12-month adjusted payout, Treasury convention: 4.20%. https://pages.stern.nyu.edu/adamodar/New_Home_Page/home.htm
A11: Operating beta build | B11: TTM revenue | C11: Revenue weight | D11: Cash-adjusted unlevered beta | E11: Basis
A12: Google Services | B12: ='Historical base'!F12 -> 367091 | C12: =B12/SUM($B$12:$B$14) -> 0.82267741 | D12: 1.01 | E12: Advertising industry proxy; January 2026 US sector data.
A13: Google Cloud | B13: ='Historical base'!F13 -> 77617 | C13: =B13/SUM($B$12:$B$14) -> 0.1739453 | D13: 1.25 | E13: System & application software proxy; infrastructure exposure warrants sensitivity.
A14: Other Bets | B14: ='Historical base'!F14 -> 1507 | C14: =B14/SUM($B$12:$B$14) -> 0.0033772957 | D14: 1.59 | E14: Internet software proxy; small revenue weight understates early-stage option value. Review through SOTP.
A15: Weighted operating beta | B15: =SUMPRODUCT(C12:C14,D12:D14) -> 1.0537057 | C15: Revenue weighting is a provisional substitute for business-value weights; not a regression estimate.
A16: Operating levered beta | B16: =B15*(1+(1-Assumptions!$B$5)*(B22+B23)/B7) -> 1.0758505 | C16: Relever using market debt/common equity. Portfolio leverage approximation; test against alternate peer weights.
A17: Cost of common equity | B17: =B8+B16*B9 -> 0.09518572 | C17: CAPM; https://pages.stern.nyu.edu/adamodar/New_Home_Page/datafile/Betas.html
A19: Debt and financing claims | B19: Amount | C19: Basis
A20: June quoted notes fair value | B20: 94900 | C20: June 2026 quoted notes fair value carried forward as a proxy, not an October bond quote.
A21: Other long-term debt proxy | B21: =1686+'Financial assets'!B70 -> 6686 | C21: June other debt 1,686 plus Waymo's USD5,000m term loan closed 8 October 2026; face value proxy. https://blog.waymo.com/blog/2026/10/waymo-closes-5-billion-debt-financing/
A22: Debt excluding finance leases | B22: =SUM(B20:B21) -> 101586 | C22: Avoid adding the current note portion again; included in outstanding-note fair value.
A23: Finance lease claim | B23: ='Sources and basis'!B55 -> 2590 | C23: June carrying-value proxy; already separate in the enterprise bridge.
A25: Borrowing-cost estimate | B25: Value | C25: Basis
A26: H1 EBIT | B26: ='Historical base'!E24 -> 80466 | C26: Six-month operating earnings; used only to assess interest coverage.
A27: H1 interest expense incl. capitalised | B27: =1811+628 -> 2439 | C27: Q2 2026 Note 7; capitalised interest included to avoid overstating coverage.
A28: Interest coverage | B28: =B26/B27 -> 32.99139 | C28: Same-period numerator and denominator.
A29: Synthetic credit spread | B29: 0.004 | C29: January 2026 Aaa/AAA coverage category synthetic spread; not an observed October traded yield. https://pages.stern.nyu.edu/adamodar/New_Home_Page/datafile/ratings.html
A30: Pre-tax borrowing cost | B30: =B8+B29 -> 0.054 | C30: Treasury plus synthetic spread; test ±50 bps. A dated traded-bond yield can replace this estimate.
A32: Mandatory convertible preferred | B32: Value | C32: Basis
A33: Total depositary shares (millions) | B33: 385 | C33: Q2 2026 Note 11; split evenly between Series A/B.
A34: Series A depositary closing price | B34: 46.32 | C34: 23 October 2026 close, GOOGM. https://www.quiverquant.com/stock/GOOGM/historical-prices/
A35: Series B depositary closing price | B35: 46.17 | C35: 23 October 2026 close, GOOGN. https://businessquant.com/stocks/googn/
A36: Preferred market claim | B36: =B33/2*(B34+B35) -> 17804.325 | C36: Market value includes conversion rights; no additional common-share dilution adjustment.
A37: Preferred required return assumption | B37: =B17 -> 0.09518572 | C37: Uses common-equity cost as a provisional equity-like risk proxy, not the 6.25% coupon or current dividend yield.
A38: Preferred-return WACC sensitivity | B38: =B36/(B7+B22+B23+B36)*(B37-B30) -> 0.00018159671 | C38: WACC change if preferred required return falls from common-equity cost to borrowing cost.
A40: Weighted average cost of capital | B40: Value | C40: Basis
A41: Total financing value | B41: =SUM(B7,B22:B23,B36) -> 4037980.3 | C41: Market values, with June debt and lease proxies.
A42: Common equity weight | B42: =B7/B41 -> 0.96979175
A43: Debt weight | B43: =SUM(B22:B23)/B41 -> 0.025799036
A44: Preferred weight | B44: =B36/B41 -> 0.0044092154
A45: Indicative WACC | B45: =B42*B17+B43*B30*(1-Assumptions!B5)+B44*B37 -> 0.093830607 | C45: One date, one base discount rate; model remains provisional pending peer and market-input review.
A48: NCI / ownership claim | B48: Value | C48: Basis
...

Sheet Operating forecast
A1: Alphabet | operating forecast
A2: USD millions. Provisional scenarios; reference segment margins are adjusted for the explicit group depreciation schedule.
A3: Selected case | B3: =Assumptions!B3 -> Base
A6: Revenue and earnings | B6: FY2025 A | C6: H1 2026 A | D6: TTM Jun26 | E6: H2 2026 E | F6: FY2026 E | G6: 2027 E | H6: 2028 E | I6: 2029 E | J6: 2030 E | K6: 2031 E
A8: Search & other | B8: ='Historical base'!C8 -> 224532 | C8: ='Historical base'!E8 -> 123670 | D8: ='Historical base'!F8 -> 243310 | E8: =('Historical base'!C8-'Historical base'!D8)*(1+Assumptions!B7) -> 141058.22 | F8: =C8+E8 -> 264728.22 | G8: =F8*(1+Assumptions!C7) -> 304437.45 | H8: =G8*(1+Assumptions!D7) -> 344014.32 | I8: =H8*(1+Assumptions!E7) -> 381855.9 | J8: =I8*(1+Assumptions!F7) -> 416222.93 | K8: =J8*(1+Assumptions!G7) -> 449520.76
A9: YouTube advertising | B9: ='Historical base'!C9 -> 40367 | C9: ='Historical base'!E9 -> 20938 | D9: ='Historical base'!F9 -> 42582 | E9: =('Historical base'!C9-'Historical base'!D9)*(1+Assumptions!B12) -> 24204.565 | F9: =C9+E9 -> 45142.565 | G9: =F9*(1+Assumptions!C12) -> 50559.673 | H9: =G9*(1+Assumptions!D12) -> 56121.237 | I9: =H9*(1+Assumptions!E12) -> 61733.361 | J9: =I9*(1+Assumptions!F12) -> 67289.363 | K9: =J9*(1+Assumptions!G12) -> 72672.512
A10: Google Network | B10: ='Historical base'!C10 -> 29792 | C10: ='Historical base'!E10 -> 14274 | D10: ='Historical base'!F10 -> 29456 | E10: =('Historical base'!C10-'Historical base'!D10)*(1+Assumptions!B17) -> 14832.845 | F10: =C10+E10 -> 29106.845 | G10: =F10*(1+Assumptions!C17) -> 28233.64 | H10: =G10*(1+Assumptions!D17) -> 27386.631 | I10: =H10*(1+Assumptions!E17) -> 26838.898 | J10: =I10*(1+Assumptions!F17) -> 26302.12 | K10: =J10*(1+Assumptions!G17) -> 25776.078
A11: Subscriptions / devices | B11: ='Historical base'!C11 -> 48030 | C11: ='Historical base'!E11 -> 25295 | D11: ='Historical base'!F11 -> 51743 | E11: =('Historical base'!C11-'Historical base'!D11)*(1+Assumptions!B22) -> 30998.154 | F11: =C11+E11 -> 56293.154 | G11: =F11*(1+Assumptions!C22) -> 64737.127 | H11: =G11*(1+Assumptions!D22) -> 73152.954 | I11: =H11*(1+Assumptions!E22) -> 81931.308 | J11: =I11*(1+Assumptions!F22) -> 90124.439 | K11: =J11*(1+Assumptions!G22) -> 98235.638
A12: Google Services | B12: ='Historical base'!C12 -> 342721 | C12: ='Historical base'!E12 -> 184177 | D12: ='Historical base'!F12 -> 367091 | E12: =SUM(E8:E11) -> 211093.78 | F12: =C12+E12 -> 395270.78 | G12: =SUM(G8:G11) -> 447967.89 | H12: =SUM(H8:H11) -> 500675.14 | I12: =SUM(I8:I11) -> 552359.46 | J12: =SUM(J8:J11) -> 599938.85 | K12: =SUM(K8:K11) -> 646204.99
A13: Google Cloud | B13: ='Historical base'!C13 -> 58705 | C13: ='Historical base'!E13 -> 44796 | D13: ='Historical base'!F13 -> 77617 | E13: ='Cloud demand'!B28 -> 59763.547 | F13: =C13+E13 -> 104559.55 | G13: ='Cloud demand'!C28 -> 155893.98 | H13: ='Cloud demand'!D28 -> 195122.58 | I13: ='Cloud demand'!E28 -> 233232.95 | J13: ='Cloud demand'!F28 -> 269641.59 | K13: ='Cloud demand'!G28 -> 301344.03
A14: Other Bets | B14: ='Historical base'!C14 -> 1537 | C14: ='Historical base'!E14 -> 793 | D14: ='Historical base'!F14 -> 1507 | E14: =('Historical base'!C14-'Historical base'!D14)*(1+Assumptions!B32) -> 785.4 | F14: =C14+E14 -> 1578.4 | G14: =F14*(1+Assumptions!C32) -> 1736.24 | H14: =G14*(1+Assumptions!D32) -> 1909.864 | I14: =H14*(1+Assumptions!E32) -> 2100.8504 | J14: =I14*(1+Assumptions!F32) -> 2310.9354 | K14: =J14*(1+Assumptions!G32) -> 2542.029
A15: Hedging | B15: ='Historical base'!C15 -> -127 | C15: ='Historical base'!E15 -> -74 | D15: ='Historical base'!F15 -> -349 | E15: =0 -> 0 | F15: =C15+E15 -> -74 | G15: =0 -> 0 | H15: =0 -> 0 | I15: =0 -> 0 | J15: =0 -> 0 | K15: =0 -> 0
A16: Total revenue | B16: ='Historical base'!C16 -> 402836 | C16: ='Historical base'!E16 -> 229692 | D16: ='Historical base'!F16 -> 445866 | E16: =SUM(E12:E15) -> 271642.73 | F16: =C16+E16 -> 501334.73 | G16: =SUM(G12:G15) -> 605598.12 | H16: =SUM(H12:H15) -> 697707.59 | I16: =SUM(I12:I15) -> 787693.26 | J16: =SUM(J12:J15) -> 871891.37 | K16: =SUM(K12:K15) -> 950091.05
A19: Segment reference earnings
A20: Services reference EBIT | B20: ='Historical base'!C20 -> 139404 | C20: ='Historical base'!E20 -> 80133 | D20: ='Historical base'!F20 -> 153792 | E20: =E12*Assumptions!B37-E48-E50 -> 92639.365 | F20: =C20+E20 -> 172772.36 | G20: =G12*Assumptions!C37-G48-G50 -> 196697.73 | H20: =H12*Assumptions!D37-H48-H50 -> 222595.92 | I20: =I12*Assumptions!E37-I48-I50 -> 245290.64 | J20: =J12*Assumptions!F37-J48-J50 -> 265730.67 | K20: =K12*Assumptions!G37-K48-K50 -> 288446.29
A21: Cloud reference EBIT | B21: ='Historical base'!C21 -> 13910 | C21: ='Historical base'!E21 -> 15412 | D21: ='Historical base'!F21 -> 24319 | E21: =E13*Assumptions!B42 -> 20561.563 | F21: =C21+E21 -> 35973.563 | G21: =G13*Assumptions!C42 -> 54562.894 | H21: =H13*Assumptions!D42 -> 70244.128 | I21: =I13*Assumptions!E42 -> 86296.191 | J21: =J13*Assumptions!F42 -> 102463.8 | K21: =K13*Assumptions!G42 -> 114510.73
A22: Other Bets loss | B22: ='Historical base'!C22 -> -7515 | C22: ='Historical base'!E22 -> -3899 | D22: ='Historical base'!F22 -> -8942 | E22: =('Historical base'!C22-'Historical base'!D22)*(1+Assumptions!B47) -> -5799.45 | F22: =C22+E22 -> -9698.45 | G22: =F22*(1+Assumptions!C47) -> -11153.218 | H22: =G22*(1+Assumptions!D47) -> -12491.604 | I22: =H22*(1+Assumptions!E47) -> -13740.764 | J22: =I22*(1+Assumptions!F47) -> -14840.025 | K22: =J22*(1+Assumptions!G47) -> -15582.026
A23: Alphabet-level costs | B23: ='Historical base'!C23 -> -16760 | C23: ='Historical base'!E23 -> -11180 | D23: ='Historical base'!F23 -> -21541 | E23: =-E64 -> -12107.692 | F23: =C23+E23 -> -23287.692 | G23: =-G64 -> -26561.556 | H23: =-H64 -> -29364.375 | I23: =-I64 -> -32072.836 | J23: =-J64 -> -34570.908 | K23: =-K64 -> -36860.523
A24: Group earnings at reference D&A | B24: ='Historical base'!C24 -> 129039 | C24: ='Historical base'!E24 -> 80466 | D24: ='Historical base'!F24 -> 147628 | E24: =SUM(E20:E23) -> 95293.786 | F24: =C24+E24 -> 175759.79 | G24: =SUM(G20:G23) -> 213545.85 | H24: =SUM(H20:H23) -> 250984.07 | I24: =SUM(I20:I23) -> 285773.23 | J24: =SUM(J20:J23) -> 318783.54 | K24: =SUM(K20:K23) -> 350514.47
A25: Reference D&A added back | C25: =C30+C31 -> 14131 | E25: =E16*Assumptions!$B$95 -> 16711.873 | F25: =C25+E25 -> 30842.873 | G25: =G16*Assumptions!$B$95 -> 37257.314 | H25: =H16*Assumptions!$B$95 -> 42924.028 | I25: =I16*Assumptions!$B$95 -> 48460.083 | J25: =J16*Assumptions!$B$95 -> 53640.079 | K25: =K16*Assumptions!$B$95 -> 58451.042
A26: Pre-D&A operating earnings (SBC retained) | C26: =C24+C25 -> 94597 | E26: =SUM(E24:E25) -> 112005.66 | F26: =C26+E26 -> 206602.66 | G26: =SUM(G24:G25) -> 250803.17 | H26: =SUM(H24:H25) -> 293908.09 | I26: =SUM(I24:I25) -> 334233.31 | J26: =SUM(J24:J25) -> 372423.62 | K26: =SUM(K24:K25) -> 408965.51
A29: Explicit depreciation and tax
A30: Modelled PP&E depreciation | C30: ='Historical base'!E39 -> 13586 | E30: ='Capital and FCFF'!B24 -> 21756.208 | F30: =C30+E30 -> 35342.207 | G30: ='Capital and FCFF'!C24 -> 59679.306 | H30: ='Capital and FCFF'!D24 -> 85811.887 | I30: ='Capital and FCFF'!E24 -> 97481.522 | J30: ='Capital and FCFF'!F24 -> 110008.95 | K30: ='Capital and FCFF'!G24 -> 137711.47
A31: Intangible amortisation | C31: ='Sources and basis'!D47 -> 545 | E31: ='Capital and FCFF'!B25 -> 747 | F31: =C31+E31 -> 1292 | G31: ='Capital and FCFF'!C25 -> 1304 | H31: ='Capital and FCFF'!D25 -> 1142 | I31: ='Capital and FCFF'!E25 -> 1096 | J31: ='Capital and FCFF'!F25 -> 1055 | K31: ='Capital and FCFF'!G25 -> 1055
A33: Consolidated EBIT | B33: ='Historical base'!C24 -> 129039 | C33: ='Historical base'!E24 -> 80466 | D33: ='Historical base'!F24 -> 147628 | E33: =E26-E30-E31 -> 89502.451 | F33: =C33+E33 -> 169968.45 | G33: =G26-G30-G31 -> 189819.86 | H33: =H26-H30-H31 -> 206954.21 | I33: =I26-I30-I31 -> 235655.79 | J33: =J26-J30-J31 -> 261359.67 | K33: =K26-K30-K31 -> 270199.04
A34: Consolidated operating margin | B34: ='Historical base'!C28 -> 0.32032639 | C34: ='Historical base'!E28 -> 0.3503213 | D34: ='Historical base'!F28 -> 0.33110396 | E34: =E33/E16 -> 0.3294859 | F34: =F33/F16 -> 0.33903187 | G34: =G33/G16 -> 0.31344196 | H34: =H33/H16 -> 0.29662026 | I34: =I33/I16 -> 0.29917203 | J34: =J33/J16 -> 0.29976173 | K34: =K33/K16 -> 0.28439279
A35: Operating tax | C35: =C33-C36 -> 16897.86 | E35: =MAX(0,E33+E31*(1-Assumptions!$B$239))*Assumptions!B77 -> 16244.901 | F35: =C35+E35 -> 33142.761 | G35: =MAX(0,G33+G31*(1-Assumptions!$B$239))*Assumptions!C77 -> 34402.295 | H35: =MAX(0,H33+H31*(1-Assumptions!$B$239))*Assumptions!D77 -> 37457.317 | I35: =MAX(0,I33+I31*(1-Assumptions!$B$239))*Assumptions!E77 -> 42615.323 | J35: =MAX(0,J33+J31*(1-Assumptions!$B$239))*Assumptions!F77 -> 47234.641 | K35: =MAX(0,K33+K31*(1-Assumptions!$B$239))*Assumptions!G77 -> 48825.728
A36: NOPAT | B36: ='Historical base'!C30 -> 101940.81 | C36: ='Historical base'!E30 -> 63568.14 | D36: ='Historical base'!F30 -> 116626.12 | E36: =E33-E35 -> 73257.55 | F36: =C36+E36 -> 136825.69 | G36: =G33-G35 -> 155417.57 | H36: =H33-H35 -> 169496.89 | I36: =I33-I35 -> 193040.47 | J36: =J33-J35 -> 214125.03 | K36: =K33-K35 -> 221373.31
A38: Cash CapEx | B38: ='Historical base'!C35 -> 91447 | C38: ='Historical base'!E35 -> 80598 | D38: ='Historical base'!F35 -> 132402 | E38: ='Capital and FCFF'!B12 -> 119402 | F38: =C38+E38 -> 200000 | G38: ='Capital and FCFF'!C12 -> 212413.98 | H38: ='Capital and FCFF'!D12 -> 209722.86 | I38: ='Capital and FCFF'!E12 -> 213367.43 | J38: ='Capital and FCFF'!F12 -> 210183.72 | K38: ='Capital and FCFF'!G12 -> 210118.62
A40: Model interpretation
A41: Reference segment EBIT uses scenario margins at the H1 2026 D&A/revenue burden. That burden is added back and replaced once by the capital schedule.
A42: Segment D&A allocation is not disclosed; forecast segment reference EBIT is not a claim of independently modelled segment GAAP profit.
A43: H2 uses prior-year H2 product revenue × selected YoY growth. FY2026 combines H1 actual and H2 estimate; only future cash flows enter the DCF.
A45: Services cost sensitivities
A46: Advertising revenue | E46: =SUM(E8:E10) -> 180095.63 | F46: =SUM(F8:F10) -> 338977.63 | G46: =SUM(G8:G10) -> 383230.77 | H46: =SUM(H8:H10) -> 427522.19 | I46: =SUM(I8:I10) -> 470428.16 | J46: =SUM(J8:J10) -> 509814.41 | K46: =SUM(K8:K10) -> 547969.35
A47: TAC rate change vs. reference | E47: =Assumptions!B153+E57 -> -0.002991728 | G47: =Assumptions!C153+G57 -> -0.0064670292 | H47: =Assumptions!D153+H57 -> -0.010312516 | I47: =Assumptions!E153+I57 -> -0.013115277 | J47: =Assumptions!F153+J57 -> -0.01529948 | K47: =Assumptions!G153+K57 -> -0.017120396
A48: Incremental TAC cost | E48: =E46*E47 -> -538.79714 | F48: =E48 -> -538.79714 | G48: =G46*G47 -> -2478.3645 | H48: =H46*H47 -> -4408.8294 | I48: =I46*I47 -> -6169.7957 | J48: =J46*J47 -> -7799.8954 | K48: =K46*K47 -> -9381.4523
A49: AI serving-cost change | E49: =Assumptions!$B$217*(E58-1) -> -0.0012147563 | G49: =Assumptions!$B$217*(G58-1) -> -0.003556448 | H49: =Assumptions!$B$217*(H58-1) -> -0.0057857385 | I49: =Assumptions!$B$217*(I58-1) -> -0.0079080231 | J49: =Assumptions!$B$217*(J58-1) -> -0.009928438 | K49: =Assumptions!$B$217*(K58-1) -> -0.011851873
A50: Incremental AI serving cost | E50: =E12*E49 -> -256.42751 | F50: =E50 -> -256.42751 | G50: =G12*G49 -> -1593.1745 | H50: =H12*H49 -> -2896.7755 | I50: =I12*I49 -> -4368.0714 | J50: =J12*J49 -> -5956.4557 | K50: =K12*K49 -> -7658.7394
A52: Reference margins already include baseline TAC, content and infrastructure costs. Only changes versus that reference are applied; D&A is replaced once at group level.
...

Sheet Cloud demand
A1: Alphabet | Cloud demand and delivery
A2: USD millions. Opening backlog is recognised once; new contracts, renewals and usage are shown separately. Financing and capacity exposures are analyst sensitivities.
A3: Selected scenario | B3: =Assumptions!B3 -> Base
A4: Valuation date | B4: =Assumptions!B4 -> 46320
A6: Cloud revenue build | B6: H2 2026 | C6: 2027 | D6: 2028 | E6: 2029 | F6: 2030 | G6: 2031 | H6: Basis
A7: June 2026 Cloud backlog | B7: ='Sources and basis'!$B$92 -> 513900 | C7: ='Sources and basis'!$B$92 -> 513900 | D7: ='Sources and basis'!$B$92 -> 513900 | E7: ='Sources and basis'!$B$92 -> 513900 | F7: ='Sources and basis'!$B$92 -> 513900 | G7: ='Sources and basis'!$B$92 -> 513900
A8: Scheduled share of opening backlog | B8: =Assumptions!B167 -> 0.1 | C8: =Assumptions!C167 -> 0.26 | D8: =Assumptions!D167 -> 0.24 | E8: =Assumptions!E167 -> 0.18 | F8: =Assumptions!F167 -> 0.13 | G8: =Assumptions!G167 -> 0.09
A9: Scheduled opening-backlog recognition | B9: =B7*B8 -> 51390 | C9: =C7*C8 -> 133614 | D9: =D7*D8 -> 123336 | E9: =E7*E8 -> 92502 | F9: =F7*F8 -> 66807 | G9: =G7*G8 -> 46251
A10: Reference demand growth | B10: =Assumptions!B27 -> 0.73064441 | C10: =Assumptions!C27 -> 0.35 | D10: =Assumptions!D27 -> 0.25 | E10: =Assumptions!E27 -> 0.2 | F10: =Assumptions!F27 -> 0.16 | G10: =Assumptions!G27 -> 0.12
A11: Revenue demand before backlog floor | B11: =('Historical base'!C13-'Historical base'!D13)*(1+B10) -> 56801.48 | C11: =('Historical base'!E13+B12)*(1+C10) -> 142094.01 | D11: =C12*(1+D10) -> 196491.18 | E11: =D12*(1+E10) -> 235789.41 | F11: =E12*(1+F10) -> 273515.72 | G11: =F12*(1+G10) -> 306337.6
A12: Planned Cloud demand | B12: =MAX(B11,B9/(1-Assumptions!$B$171)) -> 60458.824 | C12: =MAX(C11,C9/(1-Assumptions!$B$171)) -> 157192.94 | D12: =MAX(D11,D9/(1-Assumptions!$B$171)) -> 196491.18 | E12: =MAX(E11,E9/(1-Assumptions!$B$171)) -> 235789.41 | F12: =MAX(F11,F9/(1-Assumptions!$B$171)) -> 273515.72 | G12: =MAX(G11,G9/(1-Assumptions!$B$171)) -> 306337.6
A13: New contracts / usage outside opening backlog | B13: =B12-B9 -> 9068.8235 | C13: =C12-C9 -> 23578.941 | D13: =D12-D9 -> 73155.176 | E13: =E12-E9 -> 143287.41 | F13: =F12-F9 -> 206708.72 | G13: =G12-G9 -> 260086.6
A14: Opening unrecognised June backlog | B14: =B7 -> 513900 | C14: =B23 -> 463023.9 | D14: =C23 -> 330237.28 | E14: =D23 -> 206806.77 | F14: =E23 -> 113995.49 | G14: =F23 -> 46928.445
A15: Opening deferred recognition | B15: =0 -> 0 | C15: =B24 -> 513.9 | D15: =C24 -> 1341.279 | E15: =D24 -> 1246.7728 | F15: =E24 -> 937.48773 | G15: =F24 -> 677.44488
A16: Recognition due including delays | B16: =B9+B15 -> 51390 | C16: =C9+C15 -> 134127.9 | D16: =D9+D15 -> 124677.28 | E16: =E9+E15 -> 93748.773 | F16: =F9+F15 -> 67744.488 | G16: =G9+G15 -> 46928.445
A17: Required in-service PP&E (capacity requirement × annualised demand) | B17: =B31/'Capital and FCFF'!B7*Assumptions!B234 -> 214874.69 | C17: =C31/'Capital and FCFF'!C7*Assumptions!C234 -> 289611.28 | D17: =D31/'Capital and FCFF'!D7*Assumptions!D234 -> 403506.77 | E17: =E31/'Capital and FCFF'!E7*Assumptions!E234 -> 513346.22 | F17: =F31/'Capital and FCFF'!F7*Assumptions!F234 -> 617151.95 | G17: =G31/'Capital and FCFF'!G7*Assumptions!G234 -> 702942.28
A18: Average in-service PP&E | B18: =AVERAGE('Capital and FCFF'!B20-'Capital and FCFF'!B13,'Capital and FCFF'!B27) -> 214897.15 | C18: =AVERAGE('Capital and FCFF'!C20-'Capital and FCFF'!C13,'Capital and FCFF'!C27) -> 289657.19 | D18: =AVERAGE('Capital and FCFF'!D20-'Capital and FCFF'!D13,'Capital and FCFF'!D27) -> 403572.88 | E18: =AVERAGE('Capital and FCFF'!E20-'Capital and FCFF'!E13,'Capital and FCFF'!E27) -> 513374.76 | F18: =AVERAGE('Capital and FCFF'!F20-'Capital and FCFF'!F13,'Capital and FCFF'!F27) -> 617205.17 | G18: =AVERAGE('Capital and FCFF'!G20-'Capital and FCFF'!G13,'Capital and FCFF'!G27) -> 702953.24
A19: Capacity coverage (capped at 100%) | B19: =IF(B17>0,MIN(1,B18/B17),1) -> 1 | C19: =IF(C17>0,MIN(1,C18/C17),1) -> 1 | D19: =IF(D17>0,MIN(1,D18/D17),1) -> 1 | E19: =IF(E17>0,MIN(1,E18/E17),1) -> 1 | F19: =IF(F17>0,MIN(1,F18/F17),1) -> 1 | G19: =IF(G17>0,MIN(1,G18/G17),1) -> 1
A20: Delivery factor | B20: =1-Assumptions!$B$187+Assumptions!$B$187*B19 -> 1 | C20: =1-Assumptions!$B$187+Assumptions!$B$187*C19 -> 1 | D20: =1-Assumptions!$B$187+Assumptions!$B$187*D19 -> 1 | E20: =1-Assumptions!$B$187+Assumptions!$B$187*E19 -> 1 | F20: =1-Assumptions!$B$187+Assumptions!$B$187*F19 -> 1 | G20: =1-Assumptions!$B$187+Assumptions!$B$187*G19 -> 1
A21: Funding-related recognition factor | B21: =1-Assumptions!$B$172*Assumptions!$B$177 -> 0.99 | C21: =1-Assumptions!$B$172*Assumptions!$B$177 -> 0.99 | D21: =1-Assumptions!$B$172*Assumptions!$B$177 -> 0.99 | E21: =1-Assumptions!$B$172*Assumptions!$B$177 -> 0.99 | F21: =1-Assumptions!$B$172*Assumptions!$B$177 -> 0.99 | G21: =1-Assumptions!$B$172*Assumptions!$B$177 -> 0.99
A22: Opening backlog recognised | B22: =MIN(B14,B16*B20*B21) -> 50876.1 | C22: =MIN(C14,C16*C20*C21) -> 132786.62 | D22: =MIN(D14,D16*D20*D21) -> 123430.51 | E22: =MIN(E14,E16*E20*E21) -> 92811.285 | F22: =MIN(F14,F16*F20*F21) -> 67067.043 | G22: =MIN(G14,G16*G20*G21) -> 46459.16
A23: Closing unrecognised June backlog | B23: =B14-B22 -> 463023.9 | C23: =C14-C22 -> 330237.28 | D23: =D14-D22 -> 206806.77 | E23: =E14-E22 -> 113995.49 | F23: =F14-F22 -> 46928.445 | G23: =G14-G22 -> 469.28445
A24: Delayed recognition carried forward | B24: =MAX(0,B16-B22) -> 513.9 | C24: =MAX(0,C16-C22) -> 1341.279 | D24: =MAX(0,D16-D22) -> 1246.7728 | E24: =MAX(0,E16-E22) -> 937.48773 | F24: =MAX(0,F16-F22) -> 677.44488 | G24: =MAX(0,G16-G22) -> 469.28445
A25: New business after delivery constraint | B25: =B13*MIN(1,B20) -> 9068.8235 | C25: =C13*MIN(1,C20) -> 23578.941 | D25: =D13*MIN(1,D20) -> 73155.176 | E25: =E13*MIN(1,E20) -> 143287.41 | F25: =F13*MIN(1,F20) -> 206708.72 | G25: =G13*MIN(1,G20) -> 260086.6
A26: Financing-related new-business reduction | B26: =B25*Assumptions!$B$172*Assumptions!$B$182 -> 181.37647 | C26: =C25*Assumptions!$B$172*Assumptions!$B$182 -> 471.57882 | D26: =D25*Assumptions!$B$172*Assumptions!$B$182 -> 1463.1035 | E26: =E25*Assumptions!$B$172*Assumptions!$B$182 -> 2865.7482 | F26: =F25*Assumptions!$B$172*Assumptions!$B$182 -> 4134.1744 | G26: =G25*Assumptions!$B$172*Assumptions!$B$182 -> 5201.7321
A27: New business recognised | B27: =B25-B26 -> 8887.4471 | C27: =C25-C26 -> 23107.362 | D27: =D25-D26 -> 71692.073 | E27: =E25-E26 -> 140421.66 | F27: =F25-F26 -> 202574.54 | G27: =G25-G26 -> 254884.87
A28: Forecast Cloud revenue | B28: =SUM(B22,B27) -> 59763.547 | C28: =SUM(C22,C27) -> 155893.98 | D28: =SUM(D22,D27) -> 195122.58 | E28: =SUM(E22,E27) -> 233232.95 | F28: =SUM(F22,F27) -> 269641.59 | G28: =SUM(G22,G27) -> 301344.03
A29: Actual forecast revenue growth | B29: =B28/('Historical base'!C13-'Historical base'!D13)-1 -> 0.82089355 | C29: =C28/('Historical base'!E13+B28)-1 -> 0.49095886 | D29: =D28/C28-1 -> 0.25163637 | E29: =E28/D28-1 -> 0.19531501 | F29: =F28/E28-1 -> 0.15610418 | G29: =G28/F28-1 -> 0.11757254
A30: Demand less delivered revenue | B30: =B12-B28 -> 695.27647 | C30: =C12-C28 -> 1298.9578 | D30: =D12-D28 -> 1368.5973 | E30: =E12-E28 -> 2556.4632 | F30: =F12-F28 -> 3874.1315 | G30: =G12-G28 -> 4993.5716
A31: Group demand for CapEx planning | B31: =SUM('Operating forecast'!E12,'Operating forecast'!E14:'Operating forecast'!E15,B12) -> 272338.01 | C31: =SUM('Operating forecast'!G12,'Operating forecast'!G14:'Operating forecast'!G15,C12) -> 606897.07 | D31: =SUM('Operating forecast'!H12,'Operating forecast'!H14:'Operating forecast'!H15,D12) -> 699076.18 | E31: =SUM('Operating forecast'!I12,'Operating forecast'!I14:'Operating forecast'!I15,E12) -> 790249.73 | F31: =SUM('Operating forecast'!J12,'Operating forecast'!J14:'Operating forecast'!J15,F12) -> 875765.5 | G31: =SUM('Operating forecast'!K12,'Operating forecast'!K14:'Operating forecast'!K15,G12) -> 955084.62
A32: Opening backlog reconciliation | B32: =B14-B22-B23 -> 0 | C32: =C14-C22-C23 -> 0 | D32: =D14-D22-D23 -> 0 | E32: =E14-E22-E23 -> 0 | F32: =F14-F22-F23 -> 0 | G32: =G14-G22-G23 -> 0
A34: 24-month reference recognition share | B34: =SUM(B8:C8)+Assumptions!B168 -> 0.51
A35: 24-month delivered share (timing proxy) | B35: =(SUM(B22:C22)+D22*Assumptions!B168/D8)/B7 -> 0.50750494
A36: June backlog remaining at end 2031 | B36: =G23 -> 469.28445
A37: AWS H1 2026 operating margin | B37: ='Sources and basis'!B101/'Sources and basis'!B100 -> 0.38564753
A38: Cloud 2031 reference operating margin | B38: =Assumptions!G42 -> 0.38
A40: Timing: 51% by June 2028 is an analyst approximation to group guidance of just over 50%; the 2031 tail is assumed, not a disclosed contract expiry.
A41: Delivery compares average in-service PP&E with the capacity that planned demand requires (Assumptions row 234, calibrated so the Base build just covers Base demand). A shortfall cuts the delivery-sensitive half of Cloud revenue; surplus capacity does not accelerate contracted revenue. This is a capacity proxy, not measured workloads or utilisation. Delayed opening backlog stays in the roll-forward.
A42: New-business demand is the residual after opening-backlog recognition, subject to a 15% minimum mix assumption. No separate new-bookings balance is claimed.
A43: Financing exposure (20%) is an illustrative sensitivity, not an identified customer share. Deferred conversion and weaker new business are modelled separately.
...

Sheet Working capital
A1: Alphabet | operating working capital
A2: USD millions. Non-cash operating balances exclude financing and identified non-operating items. Required operating cash is added in rows 58–62; residual classifications remain provisional.
A3: Selected case | B3: =Assumptions!B3 -> Base
A4: Opening non-cash operating WC | B4: =C29 -> 26257
A6: Operating balance | B6: Dec 2025 A | C6: Jun 2026 A | E6: Dec 2026 E | F6: 2027 E | G6: 2028 E | H6: 2029 E | I6: 2030 E | J6: 2031 E
A7: Operating current assets
A8: Trade receivables | B8: ='Balance sheet'!G11 -> 62886 | C8: ='Balance sheet'!I11 -> 69175 | E8: =E35/365*Assumptions!B103 -> 77780.836 | F8: =F35/365*Assumptions!C103 -> 93957.04 | G8: =G35/365*Assumptions!D103 -> 108247.6 | H8: =H35/365*Assumptions!E103 -> 122208.65 | I8: =I35/365*Assumptions!F103 -> 135271.78 | J8: =J35/365*Assumptions!G103 -> 147404.26
A9: Inventory | B9: ='Sources and basis'!B97 -> 2439 | C9: ='Balance sheet'!I12 -> 9991 | E9: =E35*Assumptions!B108 -> 11233.948 | F9: =F35*Assumptions!C108 -> 8618.4639 | G9: =G35*Assumptions!D108 -> 4224.3216 | H9: =H35*Assumptions!E108 -> 4769.1464 | I9: =I35*Assumptions!F108 -> 5278.93 | J9: =J35*Assumptions!G108 -> 5752.3957
A10: Other current assets / operating residual | B10: ='Sources and basis'!B98 -> 13870 | C10: ='Balance sheet'!I13 -> 21884 | E10: =E35*Assumptions!B113 -> 16623.229 | F10: =F35*Assumptions!C113 -> 20080.389 | G10: =G35*Assumptions!D113 -> 23134.549 | H10: =H35*Assumptions!E113 -> 26118.289 | I10: =I35*Assumptions!F113 -> 28910.126 | J10: =J35*Assumptions!G113 -> 31503.066
A11: Less: held-for-sale PP&E | B11: ='Sources and basis'!B84 -> 0 | C11: ='Sources and basis'!C84 -> 7100
A12: Less: further non-operating adjustments | B12: 0 | C12: 0
A13: Operating current assets | B13: =SUM(B8:B10)-SUM(B11:B12) -> 79195 | C13: =SUM(C8:C10)-SUM(C11:C12) -> 93950 | E13: =SUM(E8:E10) -> 105638.01 | F13: =SUM(F8:F10) -> 122655.89 | G13: =SUM(G8:G10) -> 135606.47 | H13: =SUM(H8:H10) -> 153096.08 | I13: =SUM(I8:I10) -> 169460.83 | J13: =SUM(J8:J10) -> 184659.72
A15: Operating current liabilities
A16: Reported accounts payable | B16: ='Balance sheet'!G27 -> 12200 | C16: ='Balance sheet'!I27 -> 20258
A17: Less: CapEx creditors in AP | B17: ='Sources and basis'!D42-'Sources and basis'!B86 -> 6213 | C17: ='Sources and basis'!E42-'Sources and basis'!C86 -> 12917
A18: Operating supplier payables | B18: =B16-B17 -> 5987 | C18: =C16-C17 -> 7341 | E18: =E35*Assumptions!B118 -> 8254.2698 | F18: =F35*Assumptions!C118 -> 9970.9235 | G18: =G35*Assumptions!D118 -> 11487.468 | H18: =H35*Assumptions!E118 -> 12969.045 | I18: =I35*Assumptions!F118 -> 14355.332 | J18: =J35*Assumptions!G118 -> 15642.858
A19: Accrued compensation | B19: ='Balance sheet'!G28 -> 17546 | C19: ='Balance sheet'!I28 -> 15086 | E19: =E35*Assumptions!B123 -> 16962.8 | F19: =F35*Assumptions!C123 -> 20490.581 | G19: =G35*Assumptions!D123 -> 23607.13 | H19: =H35*Assumptions!E123 -> 26651.82 | I19: =I35*Assumptions!F123 -> 29500.687 | J19: =J35*Assumptions!G123 -> 32146.595
A20: Accrued revenue share | B20: ='Balance sheet'!G30 -> 10864 | C20: ='Balance sheet'!I30 -> 10599 | E20: =E35*Assumptions!B128 -> 11917.587 | F20: =F35*Assumptions!C128 -> 14396.107 | G20: =G35*Assumptions!D128 -> 16585.707 | H20: =H35*Assumptions!E128 -> 18724.821 | I20: =I35*Assumptions!F128 -> 20726.354 | J20: =J35*Assumptions!G128 -> 22585.295
A21: Deferred revenue | B21: ='Balance sheet'!G31 -> 6578 | C21: ='Balance sheet'!I31 -> 7154 | E21: =E35*Assumptions!B133 -> 8044.0057 | F21: =F35*Assumptions!C133 -> 9716.9305 | G21: =G35*Assumptions!D133 -> 11194.843 | H21: =H35*Assumptions!E133 -> 12638.68 | I21: =I35*Assumptions!F133 -> 13989.654 | J21: =J35*Assumptions!G133 -> 15244.381
A22: Reported other current liabilities | B22: ='Balance sheet'!G29 -> 55557 | C22: ='Balance sheet'!I29 -> 73014
A23: Less: financing, tax, leases and brokers | B23: =SUM('Sources and basis'!D36:D41) -> 7119 | C23: =SUM('Sources and basis'!E36:E41) -> 11949
A24: Less: CapEx creditors in accruals | B24: ='Sources and basis'!B86 -> 8877 | C24: ='Sources and basis'!C86 -> 16196
A25: Less: accrued fines and settlements | B25: ='Sources and basis'!B85 -> 15594 | C25: ='Sources and basis'!C85 -> 17356
A26: Residual operating accruals | B26: =B22-SUM(B23:B25) -> 23967 | C26: =C22-SUM(C23:C25) -> 27513 | E26: =E35*Assumptions!B138 -> 30935.802 | F26: =F35*Assumptions!C138 -> 37369.571 | G26: =G35*Assumptions!D138 -> 43053.359 | H26: =H35*Assumptions!E138 -> 48606.094 | I26: =I35*Assumptions!F138 -> 53801.697 | J26: =J35*Assumptions!G138 -> 58627.155
A27: Operating current liabilities | B27: =SUM(B18:B21)+B26 -> 64942 | C27: =SUM(C18:C21)+C26 -> 67693 | E27: =SUM(E18:E21)+E26 -> 76114.465 | F27: =SUM(F18:F21)+F26 -> 91944.112 | G27: =SUM(G18:G21)+G26 -> 105928.51 | H27: =SUM(H18:H21)+H26 -> 119590.46 | I27: =SUM(I18:I21)+I26 -> 132373.72 | J27: =SUM(J18:J21)+J26 -> 144246.28
A29: Net operating working capital | B29: =B13-B27 -> 14253 | C29: =C13-C27 -> 26257 | E29: =E13-E27 -> 29523.548 | F29: =F13-F27 -> 30711.781 | G29: =G13-G27 -> 29677.959 | H29: =H13-H27 -> 33505.625 | I29: =I13-I27 -> 37087.108 | J29: =J13-J27 -> 40413.44
A30: Published historical proxy | B30: ='Historical base'!D71 -> -1341 | C30: ='Historical base'!E71 -> 16001
A31: Proxy after identified adjustments | B31: =B30-B11-B12+B25 -> 14253 | C31: =C30-C11-C12+C25 -> 26257
A32: Reconciliation check | B32: =ROUND(B29-B31,6) -> 0 | C32: =ROUND(C29-C31,6) -> 0
A34: Forecast calibration
A35: Annual / TTM revenue basis | B35: ='Historical base'!C16 -> 402836 | C35: ='Historical base'!F16 -> 445866 | E35: ='Operating forecast'!F16 -> 501334.73 | F35: ='Operating forecast'!G16 -> 605598.12 | G35: ='Operating forecast'!H16 -> 697707.59 | H35: ='Operating forecast'!I16 -> 787693.26 | I35: ='Operating forecast'!J16 -> 871891.37 | J35: ='Operating forecast'!K16 -> 950091.05
A36: Receivable days | B36: =B8/B35*365 -> 56.97949 | C36: =C8/C35*365 -> 56.628841 | E36: =E8/E35*365 -> 56.628841 | F36: =F8/F35*365 -> 56.628841 | G36: =G8/G35*365 -> 56.628841 | H36: =H8/H35*365 -> 56.628841 | I36: =I8/I35*365 -> 56.628841 | J36: =J8/J35*365 -> 56.628841
A37: Inventory / revenue | B37: =B9/B35 -> 0.0060545731 | C37: =C9/C35 -> 0.022408078 | E37: =E9/E35 -> 0.022408078 | F37: =F9/F35 -> 0.014231325 | G37: =G9/G35 -> 0.0060545731 | H37: =H9/H35 -> 0.0060545731 | I37: =I9/I35 -> 0.0060545731 | J37: =J9/J35 -> 0.0060545731
A38: Other operating assets / revenue | B38: =(B10-B11-B12)/B35 -> 0.034430885 | C38: =(C10-C11-C12)/C35 -> 0.033157944 | E38: =(E10-E11-E12)/E35 -> 0.033157944 | F38: =(F10-F11-F12)/F35 -> 0.033157944 | G38: =(G10-G11-G12)/G35 -> 0.033157944 | H38: =(H10-H11-H12)/H35 -> 0.033157944 | I38: =(I10-I11-I12)/I35 -> 0.033157944 | J38: =(J10-J11-J12)/J35 -> 0.033157944
A39: Operating payables / revenue | B39: =B18/B35 -> 0.014862128 | C39: =C18/C35 -> 0.016464588 | E39: =E18/E35 -> 0.016464588 | F39: =F18/F35 -> 0.016464588 | G39: =G18/G35 -> 0.016464588 | H39: =H18/H35 -> 0.016464588 | I39: =I18/I35 -> 0.016464588 | J39: =J18/J35 -> 0.016464588
A40: Compensation accrual / revenue | B40: =B19/B35 -> 0.043556187 | C40: =C19/C35 -> 0.033835278 | E40: =E19/E35 -> 0.033835278 | F40: =F19/F35 -> 0.033835278 | G40: =G19/G35 -> 0.033835278 | H40: =H19/H35 -> 0.033835278 | I40: =I19/I35 -> 0.033835278 | J40: =J19/J35 -> 0.033835278
A41: Revenue-share accrual / revenue | B41: =B20/B35 -> 0.026968791 | C41: =C20/C35 -> 0.023771716 | E41: =E20/E35 -> 0.023771716 | F41: =F20/F35 -> 0.023771716 | G41: =G20/G35 -> 0.023771716 | H41: =H20/H35 -> 0.023771716 | I41: =I20/I35 -> 0.023771716 | J41: =J20/J35 -> 0.023771716
A42: Deferred revenue / revenue | B42: =B21/B35 -> 0.016329226 | C42: =C21/C35 -> 0.016045179 | E42: =E21/E35 -> 0.016045179 | F42: =F21/F35 -> 0.016045179 | G42: =G21/G35 -> 0.016045179 | H42: =H21/H35 -> 0.016045179 | I42: =I21/I35 -> 0.016045179 | J42: =J21/J35 -> 0.016045179
A43: Other operating accruals / revenue | B43: =B26/B35 -> 0.059495676 | C43: =C26/C35 -> 0.061706881 | E43: =E26/E35 -> 0.061706881 | F43: =F26/F35 -> 0.061706881 | G43: =G26/G35 -> 0.061706881 | H43: =H26/H35 -> 0.061706881 | I43: =I26/I35 -> 0.061706881 | J43: =J26/J35 -> 0.061706881
A44: NOWC / revenue | B44: =B29/B35 -> 0.035381644 | C44: =C29/C35 -> 0.058889891 | E44: =E29/E35 -> 0.058889891 | F44: =F29/F35 -> 0.050713138 | G44: =G29/G35 -> 0.042536386 | H44: =H29/H35 -> 0.042536386 | I44: =I29/I35 -> 0.042536386 | J44: =J29/J35 -> 0.042536386
...

Sheet Capital and FCFF
A1: Alphabet | capital deployment and FCFF
A2: USD millions. Economic depreciation / replacement prototype; asset allocation, tax treatment and deployment rates are provisional.
A3: Selected case | B3: =Assumptions!B3 -> Base
A6: Cash-flow forecast | B6: H2 2026 | C6: 2027 | D6: 2028 | E6: 2029 | F6: 2030 | G6: 2031 | H6: 2032 | I6: 2033 | J6: 2034 | K6: 2035 | L6: 2036
A7: Period length (years) | B7: 0.5 | C7: 1 | D7: 1 | E7: 1 | F7: 1 | G7: 1 | H7: 1 | I7: 1 | J7: 1 | K7: 1 | L7: 1
A8: Years since June 2026, period end | B8: =B7 -> 0.5 | C8: =B8+C7 -> 1.5 | D8: =C8+D7 -> 2.5 | E8: =D8+E7 -> 3.5 | F8: =E8+F7 -> 4.5 | G8: =F8+G7 -> 5.5 | H8: =G8+H7 -> 6.5 | I8: =H8+I7 -> 7.5 | J8: =I8+J7 -> 8.5 | ... L8: =K8+L7 -> 10.5
A9: Cash investment and deployment
A10: Planned cash CapEx | B10: =Assumptions!B93 -> 119402 | C10: ='Cloud demand'!C31*Assumptions!C57 -> 212413.98 | D10: ='Cloud demand'!D31*Assumptions!D57 -> 209722.86 | E10: ='Cloud demand'!E31*Assumptions!E57 -> 213367.43 | F10: ='Cloud demand'!F31*Assumptions!F57 -> 210183.72 | G10: ='Cloud demand'!G31*Assumptions!G57 -> 210118.62 | H10: =H95 -> 221869.37 | I10: =I95 -> 224301.41 | J10: =J95 -> 221755.27 | K10: =K95 -> 213824.35 | L10: =L95 -> 245718.64
A11: Replacement-spending floor | B11: =SUM(B21:B22,B78:B88) -> 19839.8 | C11: =SUM(C21:C22,C78:C88) -> 39679.6 | D11: =SUM(D21:D22,D78:D88) -> 39679.6 | E11: =SUM(E21:E22,E78:E88) -> 23146.433 | F11: =SUM(F21:F22,F78:F88) -> 6613.2667 | G11: =SUM(G21:G22,G78:G88) -> 39465.967 | H11: =SUM(H21:H22,H78:H88) -> 112333.92 | I11: =SUM(I21:I22,I78:I88) -> 124886.16 | ... L11: =SUM(L21:L22,L78:L88) -> 132517.84
A12: Cash CapEx | B12: =B10 -> 119402 | C12: =MAX(C10,C11) -> 212413.98 | D12: =MAX(D10,D11) -> 209722.86 | E12: =MAX(E10,E11) -> 213367.43 | F12: =MAX(F10,F11) -> 210183.72 | G12: =MAX(G10,G11) -> 210118.62 | H12: =MAX(H10,H11) -> 221869.37 | I12: =MAX(I10,I11) -> 224301.41 | J12: =MAX(J10,J11) -> 221755.27 | ... L12: =MAX(L10,L11) -> 245718.64
A13: Opening assets not in service | B13: ='Historical base'!E74 -> 122814 | C13: =B15 -> 187461.5 | D13: =C15 -> 223674.38 | E13: =D15 -> 236275.75 | F13: =E15 -> 243867.5 | G13: =F15 -> 244675.6 | H13: =G15 -> 244953.27 | I13: =H15 -> 253289.87 | J13: =I15 -> 258326.94 | ... L13: =K15 -> 253100.83
A14: Commissioned assets | B14: =MIN(B13+B12,(B13+0.5*B12)*Assumptions!B62*B7) -> 54754.5 | C14: =MIN(C13+C12,(C13+0.5*C12)*Assumptions!C62*C7) -> 176201.09 | D14: =MIN(D13+D12,(D13+0.5*D12)*Assumptions!D62*D7) -> 197121.49 | E14: =MIN(E13+E12,(E13+0.5*E12)*Assumptions!E62*E7) -> 205775.68 | F14: =MIN(F13+F12,(F13+0.5*F12)*Assumptions!F62*F7) -> 209375.62 | G14: =MIN(G13+G12,(G13+0.5*G12)*Assumptions!G62*G7) -> 209840.95 | H14: =MIN(H13+H12,(H13+0.5*H12)*Assumptions!$G$62) -> 213532.78 | I14: =MIN(I13+I12,(I13+0.5*I12)*Assumptions!$G$62) -> 219264.35 | J14: =MIN(J13+J12,(J13+0.5*J12)*Assumptions!$G$62) -> 221522.74 | K14: =MIN(K13+K12,(K13+0.5*K12)*Assumptions!$G$62) -> 219282.98 | L14: =MIN(L13+L12,(L13+0.5*L12)*Assumptions!$G$62) -> 225576.09
A15: Closing assets not in service | B15: =B13+B12-B14 -> 187461.5 | C15: =C13+C12-C14 -> 223674.38 | D15: =D13+D12-D14 -> 236275.75 | E15: =E13+E12-E14 -> 243867.5 | F15: =F13+F12-F14 -> 244675.6 | G15: =G13+G12-G14 -> 244953.27 | H15: =H13+H12-H14 -> 253289.87 | I15: =I13+I12-I14 -> 258326.94 | ... L15: =L13+L12-L14 -> 273243.38
A16: Hardware commissioned | B16: =B14*Assumptions!B72 -> 32852.7 | C16: =C14*Assumptions!C72 -> 105720.66 | D16: =D14*Assumptions!D72 -> 118272.89 | E16: =E14*Assumptions!E72 -> 123465.41 | F16: =F14*Assumptions!F72 -> 125625.37 | G16: =G14*Assumptions!G72 -> 125904.57 | H16: =H14*Assumptions!$G$72 -> 128119.67 | I16: =I14*Assumptions!$G$72 -> 131558.61 | J16: =J14*Assumptions!$G$72 -> 132913.65 | K16: =K14*Assumptions!$G$72 -> 131569.79 | L16: =L14*Assumptions!$G$72 -> 135345.65
A17: Other assets commissioned | B17: =B14-B16 -> 21901.8 | C17: =C14-C16 -> 70480.437 | D17: =D14-D16 -> 78848.595 | E17: =E14-E16 -> 82310.272 | F17: =F14-F16 -> 83750.246 | G17: =G14-G16 -> 83936.379 | H17: =H14-H16 -> 85413.111 | I17: =I14-I16 -> 87705.738 | ... L17: =L14-L16 -> 90230.435
A19: Capital and depreciation
A20: Opening net PP&E | B20: ='Historical base'!E72 -> 321212 | C20: =B26 -> 418857.79 | D20: =C26 -> 571592.46 | E20: =D26 -> 695503.43 | F20: =E26 -> 811389.33 | G20: =F26 -> 911564.11 | H20: =G26 -> 983971.26 | I20: =H26 -> 1053993 | J20: =I26 -> 1118550.3 | ... L20: =K26 -> 1215331.8
A21: Opening-asset hardware depreciation | B21: =$B$44/$B$46*MAX(0,MIN(B8,$B$46)-MAX(B8-B7,0)) -> 16533.167 | C21: =$B$44/$B$46*MAX(0,MIN(C8,$B$46)-MAX(C8-C7,0)) -> 33066.333 | D21: =$B$44/$B$46*MAX(0,MIN(D8,$B$46)-MAX(D8-D7,0)) -> 33066.333 | E21: =$B$44/$B$46*MAX(0,MIN(E8,$B$46)-MAX(E8-E7,0)) -> 16533.167 | F21: =$B$44/$B$46*MAX(0,MIN(F8,$B$46)-MAX(F8-F7,0)) -> 0 | G21: =$B$44/$B$46*MAX(0,MIN(G8,$B$46)-MAX(G8-G7,0)) -> 0 | H21: =$B$44/$B$46*MAX(0,MIN(H8,$B$46)-MAX(H8-H7,0)) -> 0 | I21: =$B$44/$B$46*MAX(0,MIN(I8,$B$46)-MAX(I8-I7,0)) -> 0 | ... L21: =$B$44/$B$46*MAX(0,MIN(L8,$B$46)-MAX(L8-L7,0)) -> 0
A22: Opening-asset other depreciation | B22: =$B$45/$B$47*MAX(0,MIN(B8,$B$47)-MAX(B8-B7,0)) -> 3306.6333 | C22: =$B$45/$B$47*MAX(0,MIN(C8,$B$47)-MAX(C8-C7,0)) -> 6613.2667 | D22: =$B$45/$B$47*MAX(0,MIN(D8,$B$47)-MAX(D8-D7,0)) -> 6613.2667 | E22: =$B$45/$B$47*MAX(0,MIN(E8,$B$47)-MAX(E8-E7,0)) -> 6613.2667 | F22: =$B$45/$B$47*MAX(0,MIN(F8,$B$47)-MAX(F8-F7,0)) -> 6613.2667 | G22: =$B$45/$B$47*MAX(0,MIN(G8,$B$47)-MAX(G8-G7,0)) -> 6613.2667 | H22: =$B$45/$B$47*MAX(0,MIN(H8,$B$47)-MAX(H8-H7,0)) -> 6613.2667 | I22: =$B$45/$B$47*MAX(0,MIN(I8,$B$47)-MAX(I8-I7,0)) -> 6613.2667 | ... L22: =$B$45/$B$47*MAX(0,MIN(L8,$B$47)-MAX(L8-L7,0)) -> 6613.2667
A23: Depreciation of new commissioned assets | B23: =SUM(B50:B60,B64:B74) -> 1916.4075 | C23: =SUM(C50:C60,C64:C74) -> 19999.706 | D23: =SUM(D50:D60,D64:D74) -> 46132.287 | E23: =SUM(E50:E60,E64:E74) -> 74335.089 | F23: =SUM(F50:F60,F64:F74) -> 103395.68 | G23: =SUM(G50:G60,G64:G74) -> 131098.2 | H23: =SUM(H50:H60,H64:H74) -> 145234.39 | I23: =SUM(I50:I60,I64:I74) -> 153130.84 | ... L23: =SUM(L50:L60,L64:L74) -> 171746.57
A24: Total PP&E economic depreciation | B24: =SUM(B21:B23) -> 21756.208 | C24: =SUM(C21:C23) -> 59679.306 | D24: =SUM(D21:D23) -> 85811.887 | E24: =SUM(E21:E23) -> 97481.522 | F24: =SUM(F21:F23) -> 110008.95 | G24: =SUM(G21:G23) -> 137711.47 | H24: =SUM(H21:H23) -> 151847.66 | I24: =SUM(I21:I23) -> 159744.1 | ... L24: =SUM(L21:L23) -> 178359.83
A25: Intangible amortisation | B25: ='Sources and basis'!E47 -> 747 | C25: ='Sources and basis'!F47 -> 1304 | D25: ='Sources and basis'!G47 -> 1142 | E25: ='Sources and basis'!H47 -> 1096 | F25: ='Sources and basis'!I47 -> 1055 | G25: =Assumptions!B94 -> 1055 | H25: =MIN(MAX(0,'Sources and basis'!$B$56-SUM($G$25:G25)),Assumptions!$B$237/Assumptions!$B$238) -> 499 | I25: =MIN(MAX(0,'Sources and basis'!$B$56-SUM($G$25:H25)),Assumptions!$B$237/Assumptions!$B$238) -> 499 | J25: =MIN(MAX(0,'Sources and basis'!$B$56-SUM($G$25:I25)),Assumptions!$B$237/Assumptions!$B$238) -> 499 | K25: =MIN(MAX(0,'Sources and basis'!$B$56-SUM($G$25:J25)),Assumptions!$B$237/Assumptions!$B$238) -> 499 | L25: =MIN(MAX(0,'Sources and basis'!$B$56-SUM($G$25:K25)),Assumptions!$B$237/Assumptions!$B$238) -> 499
A26: Closing net PP&E | B26: =B20+B12-B24 -> 418857.79 | C26: =C20+C12-C24 -> 571592.46 | D26: =D20+D12-D24 -> 695503.43 | E26: =E20+E12-E24 -> 811389.33 | F26: =F20+F12-F24 -> 911564.11 | G26: =G20+G12-G24 -> 983971.26 | H26: =H20+H12-H24 -> 1053993 | I26: =I20+I12-I24 -> 1118550.3 | ... L26: =L20+L12-L24 -> 1282690.6
A27: Closing in-service net PP&E | B27: =B26-B15 -> 231396.29 | C27: =C26-C15 -> 347918.08 | D27: =D26-D15 -> 459227.68 | E27: =E26-E15 -> 567521.83 | F27: =F26-F15 -> 666888.5 | G27: =G26-G15 -> 739017.98 | H27: =H26-H15 -> 800703.1 | I27: =I26-I15 -> 860223.34 | ... L27: =L26-L15 -> 1009447.3
A28: PP&E roll-forward check | B28: =B26-B20-B12+B24 -> 0 | C28: =C26-C20-C12+C24 -> 0 | D28: =D26-D20-D12+D24 -> 0 | E28: =E26-E20-E12+E24 -> 0 | F28: =F26-F20-F12+F24 -> 0 | G28: =G26-G20-G12+G24 -> 0 | H28: =H26-H20-H12+H24 -> -2.0372681e-10 | I28: =I26-I20-I12+I24 -> 1.4551915e-10 | ... L28: =L26-L20-L12+L24 -> 0
A30: Free cash flow
A31: NOPAT | B31: ='Operating forecast'!E36 -> 73257.55 | C31: ='Operating forecast'!G36 -> 155417.57 | D31: ='Operating forecast'!H36 -> 169496.89 | E31: ='Operating forecast'!I36 -> 193040.47 | F31: ='Operating forecast'!J36 -> 214125.03 | G31: ='Operating forecast'!K36 -> 221373.31 | H31: =Transition!C13 -> 237492.18 | I31: =Transition!D13 -> 251285.6 | J31: =Transition!E13 -> 262880.3 | K31: =Transition!F13 -> 271872.83 | L31: =Transition!G13 -> 277929.34
A32: PP&E depreciation added back | B32: =B24 -> 21756.208 | C32: =C24 -> 59679.306 | D32: =D24 -> 85811.887 | E32: =E24 -> 97481.522 | F32: =F24 -> 110008.95 | G32: =G24 -> 137711.47 | H32: =H24 -> 151847.66 | I32: =I24 -> 159744.1 | ... L32: =L24 -> 178359.83
A33: Intangible amortisation added back | B33: =B25 -> 747 | C33: =C25 -> 1304 | D33: =D25 -> 1142 | E33: =E25 -> 1096 | F33: =F25 -> 1055 | G33: =G25 -> 1055 | H33: =H25 -> 499 | I33: =I25 -> 499 | ... L33: =L25 -> 499
A34: Cash CapEx deducted | B34: =B12 -> 119402 | C34: =C12 -> 212413.98 | D34: =D12 -> 209722.86 | E34: =E12 -> 213367.43 | F34: =F12 -> 210183.72 | G34: =G12 -> 210118.62 | H34: =H12 -> 221869.37 | I34: =I12 -> 224301.41 | ... L34: =L12 -> 245718.64
A35: Closing operating WC including cash | B35: ='Working capital'!E59 -> 39550.242 | C35: ='Working capital'!F59 -> 42823.743 | D35: ='Working capital'!G59 -> 43632.111 | E35: ='Working capital'!H59 -> 49259.49 | F35: ='Working capital'!I59 -> 54524.935 | G35: ='Working capital'!J59 -> 59415.261 | H35: =Transition!C9*('Working capital'!$J$59/'Operating forecast'!$K$16) -> 64034.902 | I35: =Transition!D9*('Working capital'!$J$59/'Operating forecast'!$K$16) -> 68249.284 | J35: =Transition!E9*('Working capital'!$J$59/'Operating forecast'!$K$16) -> 71926.274 | K35: =Transition!F9*('Working capital'!$J$59/'Operating forecast'!$K$16) -> 74942.714 | L35: =Transition!G9*('Working capital'!$J$59/'Operating forecast'!$K$16) -> 77190.995
A36: Opening operating WC including cash | B36: ='Working capital'!C59 -> 35174.32 | C36: ='Working capital'!E59 -> 39550.242 | D36: ='Working capital'!F59 -> 42823.743 | E36: ='Working capital'!G59 -> 43632.111 | F36: ='Working capital'!H59 -> 49259.49 | G36: ='Working capital'!I59 -> 54524.935 | H36: =G35 -> 59415.261 | I36: =H35 -> 64034.902 | J36: =I35 -> 68249.284 | K36: =J35 -> 71926.274 | L36: =K35 -> 74942.714
A37: Increase in operating WC including cash | B37: ='Working capital'!E62 -> 4375.9221 | C37: ='Working capital'!F62 -> 3273.5012 | D37: ='Working capital'!G62 -> 808.36756 | E37: ='Working capital'!H62 -> 5627.379 | F37: ='Working capital'!I62 -> 5265.4454 | G37: ='Working capital'!J62 -> 4890.3254 | H37: =H35-H36 -> 4619.6413 | I37: =I35-I36 -> 4214.3817 | J37: =J35-J36 -> 3676.9904 | K37: =K35-K36 -> 3016.4398 | L37: =L35-L36 -> 2248.2814
A38: Projected FCFF | B38: =SUM(B31:B33)-B34-B37 -> -28017.165 | C38: =SUM(C31:C33)-C34-C37 -> 713.39555 | D38: =SUM(D31:D33)-D34-D37 -> 45919.555 | E38: =SUM(E31:E33)-E34-E37 -> 72623.186 | F38: =SUM(F31:F33)-F34-F37 -> 109739.81 | G38: =SUM(G31:G33)-G34-G37 -> 145130.84 | H38: =SUM(H31:H33)-H34-H37 -> 163349.82 | I38: =SUM(I31:I33)-I34-I37 -> 183012.91 | ... L38: =SUM(L31:L33)-L34-L37 -> 208821.25
